<?xml version="1.0" ?>
<robot name="Robot">
  <!--Generated by RobotCAD, a ROS Workbench for FreeCAD (https://github.com/drfenixion/freecad.robotcad)-->
  <link name="base_footprint"/>

  <link name="base_link">
    <visual>
      <!--base_link001/base_link001.-->
      <origin xyz="0.0 0.0 0.09" rpy="0 0 0"/>
      <geometry>
        <mesh filename="file://$(find ugv_ddsm_description)/meshes/ugv_ddsm_base_link_gbpl8r.dae"/>
      </geometry>
    </visual>
    <collision>
      <!--col__base_link003__col_base_link__BoundBox/col_base_link__BoundBox.-->
      <origin xyz="0.0 0.0 0.09" rpy="0 0 0"/>
      <geometry>
        <box size="0.37739999999999996 0.22 0.023162429423073366"/>
      </geometry>
    </collision>
    <inertial>
      <mass value="2.760747652778527"/>
      <origin xyz="-1.15033e-05 0.0 0.00595198" rpy="0 0 0"/>
      <inertia ixx="0.01755840659102684" ixy="-1.0252542012889568e-18" ixz="-2.0807598602728422e-07" iyy="0.050914127381724295" iyz="-3.7492365945096324e-21" izz="0.06826897684863655"/>
    </inertial>
  </link>
  <gazebo reference="base_link">
    <visual>
        <material>
            <ambient>0.7 0.7 0.7 1</ambient>
            <diffuse>0.7 0.7 0.7 1</diffuse>
            <specular>0.7 0.7 0.7 1</specular>
        </material>
    </visual>
  </gazebo>

  <link name="front_right_wheel">
    <visual>
      <!--DDSM116/DDSM117.Part__Feature094.-->
      <!-- <origin xyz="0.0 0.0 0.0" rpy="3.141592653589793 0 0"/> -->
      <origin xyz="0.0 0.0 -0.0" rpy="3.141592653589793 0 0"/>
      <geometry>
        <mesh filename="file://$(find ugv_ddsm_description)/meshes/ugv_ddsm_m0601c003_iehq9g.dae"/>
      </geometry>
    </visual>
    <visual>
      <!--DDSM116/DDSM117.Part__Feature095.-->
      <origin xyz="0.0 0.0 -0.0" rpy="3.141592653589793 0 0"/>
      <geometry>
        <mesh filename="file://$(find ugv_ddsm_description)/meshes/ugv_ddsm_xd6xcexbexdfxd1xb9xbbxb720220721_7jcf9m.dae"/>
      </geometry>
    </visual>
    <visual>
      <!--DDSM116/DDSM117.Part__Feature096.-->
      <origin xyz="0.0 0.0 -0.0" rpy="-3.141592653589793 0 0"/>
      <geometry>
        <mesh filename="file://$(find ugv_ddsm_description)/meshes/ugv_ddsm_m2_5017_fshvuj.dae"/>
      </geometry>
    </visual>
    <visual>
      <!--DDSM116/DDSM117.Part__Feature097.-->
      <origin xyz="0.0 0.0 -0.0" rpy="3.141592653589793 0 0"/>
      <geometry>
        <mesh filename="file://$(find ugv_ddsm_description)/meshes/ugv_ddsm_m2_5018_sgy3gq.dae"/>
      </geometry>
    </visual>
    <visual>
      <!--DDSM116/DDSM117.Part__Feature098.-->
      <origin xyz="0.0 0.0 -0.0" rpy="3.141592653589793 0 0"/>
      <geometry>
        <mesh filename="file://$(find ugv_ddsm_description)/meshes/ugv_ddsm_m2_5019_xxak0x.dae"/>
      </geometry>
    </visual>
    <visual>
      <!--DDSM116/DDSM117.Part__Feature099.-->
      <origin xyz="0.0 0.0 -0.0" rpy="-3.141592653589793 0 0"/>
      <geometry>
        <mesh filename="file://$(find ugv_ddsm_description)/meshes/ugv_ddsm_bm_sj_aa00037_004_zakpar.dae"/>
      </geometry>
    </visual>
    <collision>
      <!--col__front_right_wheel_link__cofront_right_wheel__BoundCylinder/cofront_right_wheel__BoundCylinder.-->
      <origin xyz="0.0 -0.0 0.0" rpy="1.5707963267948963 0 0"/>
      <geometry>
        <cylinder radius="0.0504" length="0.0655"/>
      </geometry>
    </collision>
    <inertial>
      <mass value="0.8518117309127473"/>
      <origin xyz="0.0 -0.0269784 0.0" rpy="0 0 0"/>
      <inertia ixx="0.000618671074192379" ixy="-3.339850159274627e-08" ixz="4.8950935571251644e-09" iyy="0.000964185267529386" iyz="-2.6295608372453394e-08" izz="0.0006187064944274721"/>
    </inertial>
  </link>
  <gazebo reference="front_right_wheel">
    <visual>
        <material>
            <ambient>0 0.0 0 1</ambient>
            <diffuse>0 0.0 0 1</diffuse>
            <specular>0 0.0 0 1</specular>
        </material>
    </visual>
  </gazebo>

  <link name="front_left_wheel">
    <visual>
      <!--DDSM118/DDSM119.Part__Feature094.-->
      <origin xyz="0.0 -0.0 0.0" rpy="3.141592653589793 0 3.1415926535897913"/>
      <geometry>
        <mesh filename="file://$(find ugv_ddsm_description)/meshes/ugv_ddsm_m0601c003_pd8e9f.dae"/>
      </geometry>
    </visual>
    <visual>
      <!--DDSM118/DDSM119.Part__Feature095.-->
      <origin xyz="0.0 -0.0 0.0" rpy="3.141592653589793 0 3.1415926535897913"/>
      <geometry>
        <mesh filename="file://$(find ugv_ddsm_description)/meshes/ugv_ddsm_xd6xcexbexdfxd1xb9xbbxb720220721_bv4pou.dae"/>
      </geometry>
    </visual>
    <visual>
      <!--DDSM118/DDSM119.Part__Feature096.-->
      <origin xyz="0.0 -0.0 0.0" rpy="-3.141592653589793 0 3.1415926535897913"/>
      <geometry>
        <mesh filename="file://$(find ugv_ddsm_description)/meshes/ugv_ddsm_m2_5017_e81gp2.dae"/>
      </geometry>
    </visual>
    <visual>
      <!--DDSM118/DDSM119.Part__Feature097.-->
      <origin xyz="0.0 -0.0 0.0" rpy="3.141592653589793 0 3.1415926535897913"/>
      <geometry>
        <mesh filename="file://$(find ugv_ddsm_description)/meshes/ugv_ddsm_m2_5018_wasqlg.dae"/>
      </geometry>
    </visual>
    <visual>
      <!--DDSM118/DDSM119.Part__Feature098.-->
      <origin xyz="0.0 -0.0 0.0" rpy="3.141592653589793 0 3.1415926535897913"/>
      <geometry>
        <mesh filename="file://$(find ugv_ddsm_description)/meshes/ugv_ddsm_m2_5019_a7cjiy.dae"/>
      </geometry>
    </visual>
    <visual>
      <!--DDSM118/DDSM119.Part__Feature099.-->
      <origin xyz="0.0 -0.0 0.0" rpy="-3.141592653589793 0 3.1415926535897913"/>
      <geometry>
        <mesh filename="file://$(find ugv_ddsm_description)/meshes/ugv_ddsm_bm_sj_aa00037_004_qkzeld.dae"/>
      </geometry>
    </visual>
    <collision>
      <!--col__front_left_wheel_link__cofront_left_wheel__BoundCylinder/cofront_left_wheel__BoundCylinder.-->
      <origin xyz="0.0 0.0 0.0" rpy="1.5707963267948963 0 3.1415926535897927"/>
      <geometry>
        <cylinder radius="0.0504" length="0.0655"/>
      </geometry>
    </collision>
    <inertial>
      <mass value="0.8518117309127473"/>
      <origin xyz="0.0 0.0269784 0.0" rpy="0 0 3.1415926535897927"/>
      <inertia ixx="0.000618671074192379" ixy="-3.339850159274627e-08" ixz="4.8950935571251644e-09" iyy="0.000964185267529386" iyz="-2.6295608372453394e-08" izz="0.0006187064944274721"/>
    </inertial>
  </link>
  <gazebo reference="front_left_wheel">
    <visual>
        <material>
            <ambient>0 0.0 0 1</ambient>
            <diffuse>0 0.0 0 1</diffuse>
            <specular>0 0.0 0 1</specular>
        </material>
    </visual>
  </gazebo> 

  <link name="rear_right_wheel">
    <visual>
      <!--DDSM120/DDSM121.DDSM117.Part__Feature094.-->
      <origin xyz="0.0 0.0 0.0" rpy="3.141592653589793 0 0"/>
      <geometry>
        <mesh filename="file://$(find ugv_ddsm_description)/meshes/ugv_ddsm_m0601c003_jv7476.dae"/>
      </geometry>
    </visual>
    <visual>
      <!--DDSM120/DDSM121.DDSM117.Part__Feature095.-->
      <origin xyz="0.0 0.0 0.0" rpy="3.141592653589793 0 0"/>
      <geometry>
        <mesh filename="file://$(find ugv_ddsm_description)/meshes/ugv_ddsm_xd6xcexbexdfxd1xb9xbbxb720220721_i3aghm.dae"/>
      </geometry>
    </visual>
    <visual>
      <!--DDSM120/DDSM121.DDSM117.Part__Feature096.-->
      <origin xyz="0.0 0.0 0.0" rpy="-3.141592653589793 0 0"/>
      <geometry>
        <mesh filename="file://$(find ugv_ddsm_description)/meshes/ugv_ddsm_m2_5017_kvfe0r.dae"/>
      </geometry>
    </visual>
    <visual>
      <!--DDSM120/DDSM121.DDSM117.Part__Feature097.-->
      <origin xyz="0.0 0.0 0.0" rpy="3.141592653589793 0 0"/>
      <geometry>
        <mesh filename="file://$(find ugv_ddsm_description)/meshes/ugv_ddsm_m2_5018_zcsbog.dae"/>
      </geometry>
    </visual>
    <visual>
      <!--DDSM120/DDSM121.DDSM117.Part__Feature098.-->
      <origin xyz="0.0 0.0 0.0" rpy="3.141592653589793 0 0"/>
      <geometry>
        <mesh filename="file://$(find ugv_ddsm_description)/meshes/ugv_ddsm_m2_5019_ox8jza.dae"/>
      </geometry>
    </visual>
    <visual>
      <!--DDSM120/DDSM121.DDSM117.Part__Feature099.-->
      <origin xyz="0.0 0.0 0.0" rpy="-3.141592653589793 0 0"/>
      <geometry>
        <mesh filename="file://$(find ugv_ddsm_description)/meshes/ugv_ddsm_bm_sj_aa00037_004_duj996.dae"/>
      </geometry>
    </visual>
    <collision>
      <!--col__rear_right_wheel_link__corear_right_wheel__BoundCylinder/corear_right_wheel__BoundCylinder.-->
      <origin xyz="0.0 -0.0 0.0" rpy="1.5707963267948963 0 0"/>
      <geometry>
        <cylinder radius="0.0504" length="0.0655"/>
      </geometry>
    </collision>
    <inertial>
      <mass value="0.8518117309127473"/>
      <origin xyz="0.0 -0.0269784 0.0" rpy="0 0 0"/>
      <inertia ixx="0.000618671074192379" ixy="-3.339850159274627e-08" ixz="4.8950935571251644e-09" iyy="0.000964185267529386" iyz="-2.6295608372453394e-08" izz="0.0006187064944274721"/>
    </inertial>
  </link>
  <gazebo reference="rear_right_wheel">
    <visual>
        <material>
            <ambient>0 0.0 0 1</ambient>
            <diffuse>0 0.0 0 1</diffuse>
            <specular>0 0.0 0 1</specular>
        </material>
    </visual>
  </gazebo> 
  
  <link name="rear_left_wheel">
    <visual>
      <!--DDSM122/DDSM123.DDSM119.Part__Feature094.-->
      <origin xyz="0.0 -0.0 0.0" rpy="3.141592653589793 0 3.1415926535897913"/>
      <geometry>
        <mesh filename="file://$(find ugv_ddsm_description)/meshes/ugv_ddsm_m0601c003_ckcpxb.dae"/>
      </geometry>
    </visual>
    <visual>
      <!--DDSM122/DDSM123.DDSM119.Part__Feature095.-->
      <origin xyz="0.0 -0.0 0.0" rpy="3.141592653589793 0 3.1415926535897913"/>
      <geometry>
        <mesh filename="file://$(find ugv_ddsm_description)/meshes/ugv_ddsm_xd6xcexbexdfxd1xb9xbbxb720220721_qzobsl.dae"/>
      </geometry>
    </visual>
    <visual>
      <!--DDSM122/DDSM123.DDSM119.Part__Feature096.-->
      <origin xyz="0.0 -0.0 0.0" rpy="-3.141592653589793 0 3.1415926535897913"/>
      <geometry>
        <mesh filename="file://$(find ugv_ddsm_description)/meshes/ugv_ddsm_m2_5017_fz8zwt.dae"/>
      </geometry>
    </visual>
    <visual>
      <!--DDSM122/DDSM123.DDSM119.Part__Feature097.-->
      <origin xyz="0.0 -0.0 0.0" rpy="3.141592653589793 0 3.1415926535897913"/>
      <geometry>
        <mesh filename="file://$(find ugv_ddsm_description)/meshes/ugv_ddsm_m2_5018_jj1l2t.dae"/>
      </geometry>
    </visual>
    <visual>
      <!--DDSM122/DDSM123.DDSM119.Part__Feature098.-->
      <origin xyz="0.0 -0.0 0.0" rpy="3.141592653589793 0 3.1415926535897913"/>
      <geometry>
        <mesh filename="file://$(find ugv_ddsm_description)/meshes/ugv_ddsm_m2_5019_w8js1l.dae"/>
      </geometry>
    </visual>
    <visual>
      <!--DDSM122/DDSM123.DDSM119.Part__Feature099.-->
      <origin xyz="0.0 -0.0 0.0" rpy="-3.141592653589793 0 3.1415926535897913"/>
      <geometry>
        <mesh filename="file://$(find ugv_ddsm_description)/meshes/ugv_ddsm_bm_sj_aa00037_004_xa8q0e.dae"/>
      </geometry>
    </visual>
    <collision>
      <!--col__rear_left_wheel_link__corear_left_wheel__BoundCylinder/corear_left_wheel__BoundCylinder.-->
      <origin xyz="0.0 0.0 0.0" rpy="1.5707963267948963 0 3.1415926535897927"/>
      <geometry>
        <cylinder radius="0.0504" length="0.0655"/>
      </geometry>
    </collision>
    <inertial>
      <mass value="0.8518117309127473"/>
      <origin xyz="0.0 0.0269784 0.0" rpy="0 0 3.1415926535897927"/>
      <inertia ixx="0.000618671074192379" ixy="-3.339850159274627e-08" ixz="4.8950935571251644e-09" iyy="0.000964185267529386" iyz="-2.6295608372453394e-08" izz="0.0006187064944274721"/>
    </inertial>
  </link>
  <gazebo reference="rear_left_wheel">
    <visual>
        <material>
            <ambient>0 0.0 0 1</ambient>
            <diffuse>0 0.0 0 1</diffuse>
            <specular>0 0.0 0 1</specular>
        </material>
    </visual>
  </gazebo>   

  <joint name="base_footprint_joint" type="fixed">
    <parent link="base_footprint"/>
    <child link="base_link"/>
    <origin xyz="0.0 0.0 0.0" rpy="0 0 0"/>
  </joint>
  
  <joint name="front_right_wheel_joint" type="continuous">
    <parent link="base_link"/>
    <child link="front_right_wheel"/>
    <origin xyz="0.12 -0.11 0.05" rpy="0 0 3.141592653589793"/>
    <axis xyz="0 -1 0"/>
  </joint>
  <joint name="front_left_wheel_joint" type="continuous">
    <parent link="base_link"/>
    <child link="front_left_wheel"/>
    <origin xyz="0.12 0.11 0.05" rpy="0 0 3.141592653589793"/>
    <axis xyz="0 -1 0"/>
  </joint>
  <joint name="rear_right_wheel_joint" type="continuous">
    <parent link="base_link"/>
    <child link="rear_right_wheel"/>
    <origin xyz="-0.12 -0.11 0.05" rpy="0 0 3.141592653589793"/>
    <axis xyz="0 -1 0"/>
  </joint>
  <joint name="rear_left_wheel_joint" type="continuous">
    <parent link="base_link"/>
    <child link="rear_left_wheel"/>
    <origin xyz="-0.12 0.11 0.05" rpy="0 0 3.141592653589793"/>
    <axis xyz="0 -1 0"/>
  </joint>
</robot>